<?xml version='1.0'?>

<robot name="udacity_bot" xmlns:xacro="http://www.ros.org/wiki/xacro">
  <xacro:include filename="$(find lasersharkcat_bot)/urdf/lasersharkcat_bot.gazebo" />
  <link name="robot_footprint"></link>

  <joint name="robot_footprint_joint" type="fixed">
    <origin xyz="0 0 0" rpy="0 0 0" />
    <parent link="robot_footprint"/>
    <child link="chassis" />
  </joint>

  <link name='chassis'>
    <pose>0 0 0.15 0 0 0</pose>

    <inertial>
      <mass value="15.0"/>
      <origin xyz="0.0 0 0" rpy=" 0 0 0"/>
      <inertia
          ixx="0.1" ixy="0" ixz="0"
          iyy="0.1" iyz="0"
          izz="0.1"
      />
    </inertial>

    <collision name='collision'>
      <origin xyz="0 0 0" rpy=" 0 0 0"/> 
      <geometry>
        <box size=".2 .15 .05"/>
      </geometry>
    </collision>

    <visual name='chassis_visual'>
      <origin xyz="0 0 0" rpy=" 0 0 0"/>
      <geometry>
        <!--box size=".4 .2 .1"/-->
        <mesh filename="file://$(find lasersharkcat_bot)/meshes/lasercatsharkrobot-base3.dae">
           <scale>0.8 0.8 0.8</scale>
        </mesh>
      </geometry>
    </visual>


    <collision name='back_caster_collision'>
      <origin xyz="-0.15 0 -0.025" rpy=" 0 0 0"/>
      <geometry>
        <sphere radius="0.024999"/>
      </geometry>
    </collision>

    <visual name='back_caster_visual'>
      <origin xyz="-0.15 0 -0.025" rpy=" 0 0 0"/>
      <geometry>
        <sphere radius="0.024999"/>
      </geometry>
    </visual>

    <collision name='front_caster_collision'>
      <origin xyz="0.15 0 -0.025" rpy=" 0 0 0"/>
      <geometry>
        <sphere radius="0.024999"/>
      </geometry>
    </collision>

    <visual name='front_caster_visual'>
      <origin xyz="0.15 0 -0.025" rpy=" 0 0 0"/>
      <geometry>
        <sphere radius="0.024999"/>
      </geometry>
    </visual>

  </link>


  <link name='left_wheel'>
    
    <inertial>
      <mass value="5.0"/>
      <origin xyz="0 0 0" rpy=" 0 0 0"/>
      <inertia
          ixx="0.1" ixy="0" ixz="0"
          iyy="0.1" iyz="0"
          izz="0.1"
      />
    </inertial>

    <collision name='left_wheel_collision'>
      <origin xyz="0 0 0" rpy=" 1.5707 0 0"/> 
      <geometry>
        <cylinder radius="0.05" length="0.03"/>
      </geometry>
    </collision>

    <visual name='left_wheel_visual'>
      <origin xyz="0 0 0" rpy=" 1.5707 0 0"/>
      <geometry>
        <cylinder radius=".05" length="0.03"/>
      </geometry>
    </visual>

  </link>

  <link name='right_wheel'>

    <inertial>
      <mass value="5.0"/>
      <origin xyz="0 0 0" rpy=" 0 0 0"/>
      <inertia
          ixx="0.1" ixy="0" ixz="0"
          iyy="0.1" iyz="0"
          izz="0.1"
      />
    </inertial>

    <collision name='right_wheel_collision'>
      <origin xyz="0 0 0" rpy=" -1.5707 0 0"/>
      <geometry>
        <cylinder radius=".05" length="0.03"/>
      </geometry>
    </collision>

    <visual name='right_wheel_visual'>
      <origin xyz="0 0 0" rpy=" -1.5707 0 0"/>
      <geometry>
        <cylinder radius=".05" length="0.03"/>
      </geometry>
    </visual>

  </link>

  <joint type="continuous" name="left_wheel_hinge">
    <origin xyz="0 0.11 0" rpy="0 0 0"/>
    <child link="left_wheel"/>
    <parent link="chassis"/>
    <axis xyz="0 1 0" rpy="0 0 0"/>
    <limit effort="10000" velocity="1000"/>
    <dynamics damping="1.0" friction="1.0"/>
  </joint>

  <joint type="continuous" name="right_wheel_hinge">
    <origin xyz="0 -0.11 0" rpy="0 0 0"/>
    <child link="right_wheel"/>
    <parent link="chassis"/>
    <axis xyz="0 1 0" rpy="0 0 0"/>
    <limit effort="10000" velocity="1000"/>
    <dynamics damping="1.0" friction="1.0"/>
  </joint>


  <joint name="camera_joint" type="fixed">
    <origin xyz="0.185 0 .03" rpy="0 0 0" />
    <child link="camera" />
    <parent link="chassis" />
  </joint>


  <link name="camera">
    <inertial>
      <mass value="0.1"/>
      <origin xyz="0 0 0" rpy=" 0 0 0"/>
      <inertia
          ixx="1e-6" ixy="0" ixz="0"
          iyy="1e-6" iyz="0"
          izz="1e-6"
      />
    </inertial>
    <collision>
      <origin xyz="0 0 0" rpy=" 0 0 0"/>
      <geometry>
        <box size="0.01 0.01 0.01" />
      </geometry>
    </collision>
    <visual>
      <origin xyz="0 0 0" rpy=" 0 0 0"/>
      <geometry>
        <box size="0.01 0.01 0.01" />
      </geometry>
    </visual>
  </link>


  <joint name="hokuyo_joint" type="fixed">
    <origin xyz=".155 0 .03"/><!-- .2555-->
    <child link="hokuyo" />
    <parent link="chassis" />
  </joint>

  <link name="hokuyo">
    <inertial>
      <mass value="0.1"/>
      <origin xyz="0.0 0 0" rpy=" 0 0 0"/>
      <inertia
          ixx="1e-6" ixy="0" ixz="0"
          iyy="1e-6" iyz="0"
          izz="1e-6"
      />
    </inertial>
    <collision>
      <origin xyz="0 0 0" rpy="0 0 0"/>
      <geometry>
        <box size="0.1 0.1 0.1" />
      </geometry>
    </collision>
    <visual>
      <origin xyz="0 0 0" rpy="0 0 0"/>
      <geometry>
        <mesh filename="package://lasersharkcat_bot/meshes/hokuyo.dae" />
        <!-- <box size="0.1 0.1 0.1" /> -->
      </geometry>
    </visual>
  </link>

</robot>
